<!-- Kinova JACO2 j2n6s200: 6-DOF non-spherical wrist arm.
     Converted from ada_ros2/ada_description URDF.
     All transforms verified against MuJoCo's URDF compiler output. -->
<mujoco model="j2n6s200">
  <compiler angle="radian" meshdir="assets"/>

  <default>
    <default class="jaco2">
      <material specular="0.5" shininess="0.4"/>
      <joint damping="0.5"/>
      <geom type="mesh" contype="1" conaffinity="1"/>
      <default class="jaco2_visual">
        <geom contype="0" conaffinity="0" group="2"/>
      </default>
      <default class="jaco2_collision">
        <geom group="3"/>
      </default>
      <default class="jaco2_dark">
        <geom rgba="0.15 0.15 0.18 1"/>
      </default>
      <default class="jaco2_ring">
        <geom rgba="0.25 0.25 0.28 1" contype="0" conaffinity="0" group="2"/>
      </default>
    </default>
  </default>

  <asset>
    <material name="carbon_fiber" rgba="0.15 0.15 0.18 1" specular="0.5" shininess="0.4"/>
    <material name="ring_metal" rgba="0.25 0.25 0.28 1" specular="0.7" shininess="0.6"/>
    <material name="finger_dark" rgba="0.1 0.1 0.12 1" specular="0.3" shininess="0.5"/>
    <mesh name="base" file="base.STL"/>
    <mesh name="shoulder" file="shoulder.STL"/>
    <mesh name="arm" file="arm.STL"/>
    <mesh name="forearm" file="forearm.STL"/>
    <mesh name="wrist" file="wrist.STL"/>
    <mesh name="hand_2finger" file="hand_2finger.STL"/>
    <mesh name="finger_proximal" file="finger_proximal.STL"/>
    <mesh name="finger_distal" file="finger_distal.STL"/>
  </asset>

  <worldbody>
    <body name="j2n6s200_link_base" childclass="jaco2">
      <geom type="mesh" mesh="base" material="carbon_fiber"/>

      <!-- Attachment site for mounting on wheelchair or other base -->
      <site name="base_mount_site" pos="0 0 0" size="0.01" rgba="0 0 1 0.3"/>

      <body name="j2n6s200_link_1" pos="0 0 0.15675" quat="0 0 1 0" gravcomp="1">
        <inertial pos="0 -0.002 -0.0605" mass="0.7477" diaginertia="0.00152032 0.00152032 0.00059816"/>
        <joint name="j2n6s200_joint_1" axis="0 0 1"/>
        <geom type="mesh" mesh="shoulder" material="carbon_fiber"/>

        <body name="j2n6s200_link_2" pos="0 0.0016 -0.11875" quat="0 0 -0.707107 0.707107" gravcomp="1">
          <inertial pos="0 -0.2065 -0.01" quat="0.707107 0.707107 0 0" mass="0.99" diaginertia="0.0105022 0.0105022 0.000792"/>
          <joint name="j2n6s200_joint_2" axis="0 0 1" range="0.820305 5.46288" limited="true"/>
          <geom type="mesh" mesh="arm" material="carbon_fiber"/>

          <body name="j2n6s200_link_3" pos="0 -0.41 0" quat="0 0 1 0" gravcomp="1">
            <inertial pos="0 0.081 -0.0086" quat="0.707107 0.707107 0 0" mass="0.6763" diaginertia="0.00142022 0.00142022 0.000304335"/>
            <joint name="j2n6s200_joint_3" axis="0 0 1" range="0.331613 5.95157" limited="true"/>
            <geom type="mesh" mesh="forearm" material="carbon_fiber"/>

            <body name="j2n6s200_link_4" pos="0 0.2073 -0.0114" quat="0 0 -0.707107 0.707107" gravcomp="1">
              <inertial pos="0 -0.037 -0.0642" quat="0.5 0.5 -0.5 0.5" mass="0.426367" diaginertia="0.0001428 7.73497e-05 7.73497e-05"/>
              <joint name="j2n6s200_joint_4" axis="0 0 1"/>
              <geom type="mesh" mesh="wrist" material="carbon_fiber"/>

              <body name="j2n6s200_link_5" pos="0 -0.03703 -0.06414" quat="0 0 0.5 0.866025" gravcomp="1">
                <inertial pos="0 -0.037 -0.0642" quat="0.5 0.5 -0.5 0.5" mass="0.426367" diaginertia="0.0001428 7.73497e-05 7.73497e-05"/>
                <joint name="j2n6s200_joint_5" axis="0 0 1"/>
                <geom type="mesh" mesh="wrist" material="carbon_fiber"/>

                <body name="j2n6s200_link_6" pos="0 -0.03703 -0.06414" quat="0 0 0.5 0.866025" gravcomp="1">
                  <inertial pos="0 0 -0.06" mass="0.78" diaginertia="0.000624 0.00037 0.00037"/>
                  <joint name="j2n6s200_joint_6" axis="0 0 1"/>
                  <geom type="mesh" mesh="hand_2finger" material="carbon_fiber"/>

                  <!-- Tool attachment site — articutool/gripper attaches here -->
                  <site name="tool_attachment_site" pos="0 0 -0.16" quat="0 1 0 0" size="0.01" rgba="1 0 0 0.3"/>

                  <!-- EE site for IK (at the URDF end_effector frame) -->
                  <site name="ee_site" pos="0 0 -0.16" quat="0 0.707107 0.707107 0" size="0.005" rgba="0 1 0 1"/>

                  <!-- Fingers -->
                  <body name="j2n6s200_link_finger_1" pos="-0.0025 0.03095 -0.11482" quat="0.314405 -0.633364 -0.314405 0.633364" gravcomp="1">
                    <inertial pos="0.044 -0.0015 0" mass="0.02" diaginertia="1.1305e-05 9.885e-06 1.57999e-06"/>
                    <joint name="j2n6s200_joint_finger_1" axis="0 0 1" range="0 1.51" limited="true"/>
                    <geom type="mesh" mesh="finger_proximal" material="finger_dark"/>
                    <geom pos="0.044 -0.003 0" type="mesh" mesh="finger_distal" material="finger_dark"/>
                  </body>
                  <body name="j2n6s200_link_finger_2" pos="-0.0025 -0.03095 -0.11482" quat="0.633364 -0.314405 0.633364 -0.314405" gravcomp="1">
                    <inertial pos="0.044 -0.0015 0" mass="0.02" diaginertia="1.1305e-05 9.885e-06 1.57999e-06"/>
                    <joint name="j2n6s200_joint_finger_2" axis="0 0 1" range="0 1.51" limited="true"/>
                    <geom type="mesh" mesh="finger_proximal" material="finger_dark"/>
                    <geom pos="0.044 -0.003 0" type="mesh" mesh="finger_distal" material="finger_dark"/>
                  </body>

                </body>
              </body>
            </body>
          </body>
        </body>
      </body>
    </body>
  </worldbody>

  <actuator>
    <general name="act_j2n6s200_joint_1" joint="j2n6s200_joint_1" gaintype="fixed" biastype="affine" gainprm="50" biasprm="0 -50 -5"/>
    <general name="act_j2n6s200_joint_2" joint="j2n6s200_joint_2" gaintype="fixed" biastype="affine" gainprm="80" biasprm="0 -80 -8" ctrlrange="0.820305 5.46288"/>
    <general name="act_j2n6s200_joint_3" joint="j2n6s200_joint_3" gaintype="fixed" biastype="affine" gainprm="50" biasprm="0 -50 -5" ctrlrange="0.331613 5.95157"/>
    <general name="act_j2n6s200_joint_4" joint="j2n6s200_joint_4" gaintype="fixed" biastype="affine" gainprm="30" biasprm="0 -30 -3"/>
    <general name="act_j2n6s200_joint_5" joint="j2n6s200_joint_5" gaintype="fixed" biastype="affine" gainprm="30" biasprm="0 -30 -3"/>
    <general name="act_j2n6s200_joint_6" joint="j2n6s200_joint_6" gaintype="fixed" biastype="affine" gainprm="30" biasprm="0 -30 -3"/>
  </actuator>

  <keyframe>
    <key name="above_plate" qpos="-2.579 3.010 1.770 -2.076 -1.791 2.858 1.33 1.33"/>
    <key name="resting" qpos="-1.860 2.181 0.364 -5.187 -0.470 -0.814 1.33 1.33"/>
    <key name="staging" qpos="-2.122 4.496 4.022 -4.710 -2.493 -1.926 1.33 1.33"/>
    <key name="stow" qpos="-1.521 2.601 0.328 -4.000 0.228 3.879 1.33 1.33"/>
  </keyframe>
</mujoco>
