<!-- Permobil wheelchair with tilt joint.
     The arm attaches at arm_attachment_site on the tilt body. -->
<mujoco model="wheelchair">
  <compiler angle="radian" meshdir="assets"/>

  <asset>
    <material name="wheelchair_metal" rgba="0.3 0.3 0.35 1" specular="0.4" shininess="0.3"/>
    <mesh name="wheelchair" file="wheelchair.stl"/>
  </asset>

  <worldbody>
    <body name="wheelchair_base" pos="0.02 -0.02 -0.05">
      <geom name="wheelchair_visual" type="mesh" mesh="wheelchair" material="wheelchair_metal"
            contype="1" conaffinity="1"/>

      <!-- Tilt mechanism -->
      <body name="tilt_body" pos="-0.02 0.02 0.05">
        <inertial pos="0 0 0" mass="5.0" diaginertia="0.1 0.1 0.1"/>
        <joint name="robot_tilt" axis="-1 0 0" range="-3.14159 3.14159" limited="true" damping="5.0"/>

        <!-- Arm mounts here -->
        <site name="arm_attachment_site" pos="0 0 0" size="0.01" rgba="0 0 1 0.3"/>
      </body>
    </body>
  </worldbody>

  <actuator>
    <general name="act_robot_tilt" joint="robot_tilt" gaintype="fixed" biastype="affine"
             gainprm="100" biasprm="0 -100 -20"/>
  </actuator>
</mujoco>
