<robot name="ada">
  <material name="aluminum">
    <color rgba="0.4 0.4 0.4 1"/>
  </material>
  <material name="plastic">
    <color rgba="0.1 0.1 0.1 1"/>
  </material>
  <link name="root"/>
  <link name="root_tilt"/>
  <joint name="robot_tilt" type="revolute">
    <origin rpy="0 0 0" xyz="0 0 0"/>
    <child link="root_tilt"/>
    <parent link="root"/>
    <axis xyz="-1 0 0"/>
    <limit effort="80" lower="-3.141592653589793" upper="3.141592653589793" velocity="0.15"/>
    <dynamics damping="0.0" friction="0.0"/>
  </joint>
  <link name="j2n6s200_link_base">
    <visual>
      <geometry>
        <mesh filename="meshes/base.STL"/>
      </geometry>
      <material name="carbon_fiber">
        <color rgba="0.792156862745098 0.819607843137255 0.933333333333333 1"/>
      </material>
    </visual>
    <collision>
      <geometry>
        <mesh filename="meshes/base.STL"/>
      </geometry>
    </collision>
    <inertial>
      <mass value="0.46784"/>
      <origin rpy="0 0 0" xyz="0 0 0.1255"/>
      <inertia ixx="0.000951270861568" ixy="0" ixz="0" iyy="0.000951270861568" iyz="0" izz="0.00037427200000000004"/>
    </inertial>
  </link>
  <joint name="j2n6s200_joint_base" type="fixed">
    <parent link="root_tilt"/>
    <child link="j2n6s200_link_base"/>
    <axis xyz="0 0 0"/>
    <origin rpy="0 0 0" xyz="0 0 0"/>
    <dynamics damping="0.0" friction="0.0"/>
  </joint>
  <link name="j2n6s200_link_1">
    <visual>
      <geometry>
        <mesh filename="meshes/shoulder.STL"/>
      </geometry>
      <material name="carbon_fiber">
        <color rgba="0.792156862745098 0.819607843137255 0.933333333333333 1"/>
      </material>
    </visual>
    <visual>
      <geometry>
        <mesh filename="meshes/ring_big.STL"/>
      </geometry>
    </visual>
    <collision>
      <geometry>
        <mesh filename="meshes/shoulder.STL"/>
      </geometry>
    </collision>
    <inertial>
      <mass value="0.7477"/>
      <origin xyz="0 -0.002 -0.0605"/>
      <inertia ixx="0.0015203172520400004" ixy="0" ixz="0" iyy="0.0015203172520400004" iyz="0" izz="0.00059816"/>
    </inertial>
  </link>
  <joint name="j2n6s200_joint_1" type="continuous">
    <parent link="j2n6s200_link_base"/>
    <child link="j2n6s200_link_1"/>
    <axis xyz="0 0 1"/>
    <limit effort="40" velocity="0.6283185307179586"/>
    <origin rpy="0 3.141592653589793 0" xyz="0 0 0.15675"/>
    <dynamics damping="0.0" friction="0.0"/>
  </joint>
  <link name="j2n6s200_link_2">
    <visual>
      <geometry>
        <mesh filename="meshes/arm.STL"/>
      </geometry>
      <material name="carbon_fiber">
        <color rgba="0.792156862745098 0.819607843137255 0.933333333333333 1"/>
      </material>
    </visual>
    <visual>
      <geometry>
        <mesh filename="meshes/ring_big.STL"/>
      </geometry>
    </visual>
    <collision>
      <geometry>
        <mesh filename="meshes/arm.STL"/>
      </geometry>
    </collision>
    <inertial>
      <mass value="0.99"/>
      <origin xyz="0 -0.2065 -0.01"/>
      <inertia ixx="0.010502207990999999" ixy="0" ixz="0" iyy="0.0007920000000000001" iyz="0" izz="0.010502207990999999"/>
    </inertial>
  </link>
  <joint name="j2n6s200_joint_2" type="revolute">
    <parent link="j2n6s200_link_1"/>
    <child link="j2n6s200_link_2"/>
    <axis xyz="0 0 1"/>
    <limit effort="80" lower="0.8203047484373349" upper="5.462880558742252" velocity="0.6283185307179586"/>
    <origin rpy="-1.5707963267948966 0 3.141592653589793" xyz="0 0.0016 -0.11875"/>
    <dynamics damping="0.0" friction="0.0"/>
  </joint>
  <link name="j2n6s200_link_3">
    <visual>
      <geometry>
        <mesh filename="meshes/forearm.STL"/>
      </geometry>
      <material name="carbon_fiber">
        <color rgba="0.792156862745098 0.819607843137255 0.933333333333333 1"/>
      </material>
    </visual>
    <visual>
      <geometry>
        <mesh filename="meshes/ring_big.STL"/>
      </geometry>
    </visual>
    <collision>
      <geometry>
        <mesh filename="meshes/forearm.STL"/>
      </geometry>
    </collision>
    <inertial>
      <mass value="0.6763"/>
      <origin xyz="0 0.081 -0.0086"/>
      <inertia ixx="0.0014202243190800001" ixy="0" ixz="0" iyy="0.000304335" iyz="0" izz="0.0014202243190800001"/>
    </inertial>
  </link>
  <joint name="j2n6s200_joint_3" type="revolute">
    <parent link="j2n6s200_link_2"/>
    <child link="j2n6s200_link_3"/>
    <axis xyz="0 0 1"/>
    <limit effort="40" lower="0.33161255787892263" upper="5.951572749300664" velocity="0.6283185307179586"/>
    <origin rpy="0 3.141592653589793 0" xyz="0 -0.410 0"/>
    <dynamics damping="0.0" friction="0.0"/>
  </joint>
  <link name="j2n6s200_link_4">
    <visual>
      <geometry>
        <mesh filename="meshes/wrist.STL"/>
      </geometry>
      <material name="carbon_fiber">
        <color rgba="0.792156862745098 0.819607843137255 0.933333333333333 1"/>
      </material>
    </visual>
    <visual>
      <geometry>
        <mesh filename="meshes/ring_small.STL"/>
      </geometry>
    </visual>
    <collision>
      <geometry>
        <mesh filename="meshes/wrist.STL"/>
      </geometry>
    </collision>
    <inertial>
      <mass value="0.426367"/>
      <origin xyz="0 -0.037 -0.0642"/>
      <inertia ixx="7.734969059999999e-05" ixy="0" ixz="0" iyy="7.734969059999999e-05" iyz="0" izz="0.0001428"/>
    </inertial>
  </link>
  <joint name="j2n6s200_joint_4" type="continuous">
    <parent link="j2n6s200_link_3"/>
    <child link="j2n6s200_link_4"/>
    <axis xyz="0 0 1"/>
    <limit effort="20" velocity="0.8377580409572781"/>
    <origin rpy="-1.5707963267948966 0 3.141592653589793" xyz="0 0.2073 -0.0114"/>
    <dynamics damping="0.0" friction="0.0"/>
  </joint>
  <link name="j2n6s200_link_5">
    <visual>
      <geometry>
        <mesh filename="meshes/wrist.STL"/>
      </geometry>
      <material name="carbon_fiber">
        <color rgba="0.792156862745098 0.819607843137255 0.933333333333333 1"/>
      </material>
    </visual>
    <visual>
      <geometry>
        <mesh filename="meshes/ring_small.STL"/>
      </geometry>
    </visual>
    <collision>
      <geometry>
        <mesh filename="meshes/wrist.STL"/>
      </geometry>
    </collision>
    <inertial>
      <mass value="0.426367"/>
      <origin xyz="0 -0.037 -0.0642"/>
      <inertia ixx="7.734969059999999e-05" ixy="0" ixz="0" iyy="7.734969059999999e-05" iyz="0" izz="0.0001428"/>
    </inertial>
  </link>
  <joint name="j2n6s200_joint_5" type="continuous">
    <parent link="j2n6s200_link_4"/>
    <child link="j2n6s200_link_5"/>
    <axis xyz="0 0 1"/>
    <limit effort="20" velocity="0.8377580409572781"/>
    <origin rpy="1.0471975511965976 0 3.141592653589793" xyz="0 -0.03703 -0.06414"/>
    <dynamics damping="0.0" friction="0.0"/>
  </joint>
  <link name="j2n6s200_link_6">
    <visual>
      <geometry>
        <mesh filename="meshes/hand_2finger.STL"/>
      </geometry>
      <material name="carbon_fiber">
        <color rgba="0.792156862745098 0.819607843137255 0.933333333333333 1"/>
      </material>
    </visual>
    <visual>
      <geometry>
        <mesh filename="meshes/ring_small.STL"/>
      </geometry>
    </visual>
    <collision>
      <geometry>
        <mesh filename="meshes/hand_2finger.STL"/>
      </geometry>
    </collision>
    <inertial>
      <mass value="0.78"/>
      <origin xyz="0 0 -0.06"/>
      <inertia ixx="0.00037049851799999997" ixy="0" ixz="0" iyy="0.00037049851799999997" iyz="0" izz="0.0006240000000000001"/>
    </inertial>
  </link>
  <joint name="j2n6s200_joint_6" type="continuous">
    <parent link="j2n6s200_link_5"/>
    <child link="j2n6s200_link_6"/>
    <axis xyz="0 0 1"/>
    <limit effort="20" velocity="0.8377580409572781"/>
    <origin rpy="1.0471975511965976 0 3.141592653589793" xyz="0 -0.03703 -0.06414"/>
    <dynamics damping="0.0" friction="0.0"/>
  </joint>
  <link name="j2n6s200_end_effector"/>
  <joint name="j2n6s200_joint_end_effector" type="fixed">
    <parent link="j2n6s200_link_6"/>
    <child link="j2n6s200_end_effector"/>
    <axis xyz="0 0 0"/>
    <origin rpy="3.141592653589793 0 1.5707963267948966" xyz="0 0 -0.1600"/>
  </joint>
  <link name="j2n6s200_link_finger_1">
    <visual>
      <geometry>
        <mesh filename="meshes/finger_proximal.STL"/>
      </geometry>
      <material name="carbon_fiber">
        <color rgba="0.792156862745098 0.819607843137255 0.933333333333333 1"/>
      </material>
    </visual>
    <collision>
      <geometry>
        <mesh filename="meshes/finger_proximal.STL"/>
      </geometry>
    </collision>
    <inertial>
      <mass value="0.01"/>
      <origin xyz="0.022 0 0"/>
      <inertia ixx="7.8999684e-07" ixy="0" ixz="0" iyy="7.8999684e-07" iyz="0" izz="8e-08"/>
    </inertial>
  </link>
  <joint name="j2n6s200_joint_finger_1" type="revolute">
    <parent link="j2n6s200_link_6"/>
    <child link="j2n6s200_link_finger_1"/>
    <axis xyz="0 0 1"/>
    <origin rpy="-1.570796327 .649262481663582 1.57079632679490" xyz="-0.0025 0.03095 -0.11482"/>
    <limit effort="2" lower="0" upper="1.51" velocity="1"/>
  </joint>
  <link name="j2n6s200_link_finger_tip_1">
    <visual>
      <geometry>
        <mesh filename="meshes/finger_distal.STL"/>
      </geometry>
      <material name="carbon_fiber">
        <color rgba="0.792156862745098 0.819607843137255 0.933333333333333 1"/>
      </material>
    </visual>
    <collision>
      <geometry>
        <mesh filename="meshes/finger_distal.STL"/>
      </geometry>
    </collision>
    <inertial>
      <mass value="0.01"/>
      <origin xyz="0.022 0 0"/>
      <inertia ixx="7.8999684e-07" ixy="0" ixz="0" iyy="7.8999684e-07" iyz="0" izz="8e-08"/>
    </inertial>
  </link>
  <joint name="j2n6s200_joint_finger_tip_1" type="fixed">
    <parent link="j2n6s200_link_finger_1"/>
    <child link="j2n6s200_link_finger_tip_1"/>
    <axis xyz="0 0 1"/>
    <origin rpy="0 0 0" xyz="0.044 -0.003 0"/>
    <limit effort="2" lower="0" upper="2" velocity="1"/>
  </joint>
  <link name="j2n6s200_link_finger_2">
    <visual>
      <geometry>
        <mesh filename="meshes/finger_proximal.STL"/>
      </geometry>
      <material name="carbon_fiber">
        <color rgba="0.792156862745098 0.819607843137255 0.933333333333333 1"/>
      </material>
    </visual>
    <collision>
      <geometry>
        <mesh filename="meshes/finger_proximal.STL"/>
      </geometry>
    </collision>
    <inertial>
      <mass value="0.01"/>
      <origin xyz="0.022 0 0"/>
      <inertia ixx="7.8999684e-07" ixy="0" ixz="0" iyy="7.8999684e-07" iyz="0" izz="8e-08"/>
    </inertial>
  </link>
  <joint name="j2n6s200_joint_finger_2" type="revolute">
    <parent link="j2n6s200_link_6"/>
    <child link="j2n6s200_link_finger_2"/>
    <axis xyz="0 0 1"/>
    <origin rpy="-1.570796327 .649262481663582 -1.57079632679490" xyz="-0.0025 -0.03095 -0.11482"/>
    <limit effort="2" lower="0" upper="1.51" velocity="1"/>
  </joint>
  <link name="j2n6s200_link_finger_tip_2">
    <visual>
      <geometry>
        <mesh filename="meshes/finger_distal.STL"/>
      </geometry>
      <material name="carbon_fiber">
        <color rgba="0.792156862745098 0.819607843137255 0.933333333333333 1"/>
      </material>
    </visual>
    <collision>
      <geometry>
        <mesh filename="meshes/finger_distal.STL"/>
      </geometry>
    </collision>
    <inertial>
      <mass value="0.01"/>
      <origin xyz="0.022 0 0"/>
      <inertia ixx="7.8999684e-07" ixy="0" ixz="0" iyy="7.8999684e-07" iyz="0" izz="8e-08"/>
    </inertial>
  </link>
  <joint name="j2n6s200_joint_finger_tip_2" type="fixed">
    <parent link="j2n6s200_link_finger_2"/>
    <child link="j2n6s200_link_finger_tip_2"/>
    <axis xyz="0 0 1"/>
    <origin rpy="0 0 0" xyz="0.044 -0.003 0"/>
    <limit effort="2" lower="0" upper="2" velocity="1"/>
  </joint>
  <link name="FTArmMount">
    <visual>
      <geometry>
        <mesh filename="meshes/forque/2024_01_18_FTArmMount.STL" scale="0.001 0.001 0.001"/>
      </geometry>
      <material name="abs">
        <color rgba="0.4 0.4 0.4 1"/>
      </material>
    </visual>
    <collision>
      <geometry>
        <mesh filename="meshes/forque/2024_01_18_FTArmMount.STL" scale="0.001 0.001 0.001"/>
      </geometry>
    </collision>
    <inertial>
      <origin rpy="0 0 0" xyz="0.010957 -0.019223 -0.03777"/>
      <mass value="0.03783"/>
      <inertia ixx="0.000018817" ixy="-0.0000003327" ixz="-0.000000092476" iyy="0.00001119989" iyz="-0.00000120296" izz="0.000026883"/>
    </inertial>
  </link>
  <joint name="FTArmMount_to_arm" type="fixed">
    <parent link="j2n6s200_link_6"/>
    <child link="FTArmMount"/>
    <axis xyz="0 0 1"/>
    <origin rpy="1.5707963267948966 0 1.5707963267948966" xyz="0.0065 -0.011 -0.0075"/>
  </joint>
  <link name="FTMount">
    <visual>
      <geometry>
        <mesh filename="meshes/forque/2024_01_18_FTMount.STL" scale="0.001 0.001 0.001"/>
      </geometry>
      <material name="abs">
        <color rgba="0.4 0.4 0.4 1"/>
      </material>
    </visual>
    <collision>
      <geometry>
        <mesh filename="meshes/forque/2024_01_18_FTMount.STL" scale="0.001 0.001 0.001"/>
      </geometry>
    </collision>
    <inertial>
      <origin rpy="0 0 0" xyz="0.010934 -0.138522 -0.05066"/>
      <mass value="0.103"/>
      <inertia ixx="0.00017623" ixy="0.00000095729" ixz="-0.0000000562908" iyy="0.000068428" iyz="-0.00001757133" izz="0.00021455"/>
    </inertial>
  </link>
  <joint name="FTMount_to_world" type="fixed">
    <parent link="FTArmMount"/>
    <child link="FTMount"/>
    <axis xyz="0 0 1"/>
    <origin rpy="0 0 0" xyz="0 0 -0.005"/>
  </joint>
  <link name="FT">
    <visual>
      <geometry>
        <mesh filename="meshes/forque/2023_03_09_wirelessFT.STL" scale="0.001 0.001 0.001"/>
      </geometry>
      <material name="abs">
        <color rgba="0.4 0.4 0.4 1"/>
      </material>
    </visual>
    <collision>
      <geometry>
        <mesh filename="meshes/forque/2023_03_09_wirelessFT.STL" scale="0.001 0.001 0.001"/>
      </geometry>
    </collision>
    <inertial>
      <origin rpy="0 0 0" xyz="0.0111446 -0.0882070 -0.0544936"/>
      <mass value="0.28"/>
      <inertia ixx="0.000543925" ixy="-0.00000128367" ixz="0" iyy="0.000165428" iyz="-0.00000001487288" izz="0.000691232"/>
    </inertial>
  </link>
  <joint name="FT_to_FTMount" type="fixed">
    <parent link="FTMount"/>
    <child link="FT"/>
    <axis xyz="0 0 1"/>
    <origin rpy="0 0 0" xyz="0 0 0"/>
  </joint>
  <link name="forkHandle">
    <visual>
      <geometry>
        <mesh filename="meshes/forque/2024_06_24_forkHandleHollow.STL" scale="0.001 0.001 0.001"/>
      </geometry>
      <material name="abs">
        <color rgba="0.4 0.4 0.4 1"/>
      </material>
    </visual>
    <collision>
      <geometry>
        <mesh filename="meshes/forque/2024_06_24_forkHandleHollow.STL" scale="0.001 0.001 0.001"/>
      </geometry>
    </collision>
    <inertial>
      <origin rpy="0 0 0" xyz="0.011097 -0.162629 -0.011948"/>
      <mass value="0.028"/>
      <inertia ixx="0.00003114" ixy="-0.00000050626" ixz="0.000000082271" iyy="0.000011867" iyz="0.00000054005" izz="0.000038478"/>
    </inertial>
  </link>
  <joint name="forkHandle_to_FTMount" type="fixed">
    <parent link="FTMount"/>
    <child link="forkHandle"/>
    <axis xyz="0 0 1"/>
    <origin rpy="-0.025 0 -0.0065" xyz="0 0.005 0.0013"/>
  </joint>
  <link name="forkHandleCover">
    <visual>
      <geometry>
        <mesh filename="meshes/forque/2024_06_24_forkHandleCover.STL" scale="0.001 0.001 0.001"/>
      </geometry>
      <material name="abs">
        <color rgba="0.4 0.4 0.4 1"/>
      </material>
    </visual>
    <collision>
      <geometry>
        <mesh filename="meshes/forque/2024_06_24_forkHandleCover.STL" scale="0.001 0.001 0.001"/>
      </geometry>
    </collision>
    <inertial>
      <origin rpy="0 0 0" xyz="0.011157 -0.168451 0.006404"/>
      <mass value="0.004"/>
      <inertia ixx="0.0000027878" ixy="0.00000000012805" ixz="0.00000000006585" iyy="0.00000064518" iyz="0.00000016201" izz="0.000003363634"/>
    </inertial>
  </link>
  <joint name="forkHandleCover_to_forkHandle" type="fixed">
    <parent link="forkHandle"/>
    <child link="forkHandleCover"/>
    <axis xyz="0 0 1"/>
    <origin rpy="0 0 0" xyz="0 0 0"/>
  </joint>
  <link name="forque">
    <visual>
      <geometry>
        <mesh filename="meshes/forque/ATI-9105-TW-NANO25-E.STL" scale="0.001 0.001 0.001"/>
      </geometry>
      <material name="abs">
        <color rgba="0.4 0.4 0.4 1"/>
      </material>
    </visual>
    <collision>
      <geometry>
        <mesh filename="meshes/forque/ATI-9105-TW-NANO25-E.STL" scale="0.001 0.001 0.001"/>
      </geometry>
    </collision>
    <inertial>
      <origin rpy="0 0 0" xyz="0.0124692 0.0137169 0.010558"/>
      <mass value="0.0634"/>
      <inertia ixx="0.000005235822" ixy="-0.0000003129932" ixz="0.000000013798" iyy="0.000006264852" iyz="-0.00000004033694" izz="0.00000640797"/>
    </inertial>
  </link>
  <joint name="forque_to_forkHandle" type="fixed">
    <parent link="forkHandle"/>
    <child link="forque"/>
    <axis xyz="0 0 1"/>
    <origin rpy="1.5707963267948966 1.0471975511965976 0" xyz="-0.00634 -0.222553 -0.004286"/>
  </joint>
  <link name="forkTine">
    <visual>
      <geometry>
        <mesh filename="meshes/forque/fork_tine.STL" scale="0.001 0.001 0.001"/>
      </geometry>
      <material name="abs">
        <color rgba="0.4 0.4 0.4 1"/>
      </material>
    </visual>
    <collision>
      <geometry>
        <mesh filename="meshes/forque/fork_tine.STL" scale="0.001 0.001 0.001"/>
      </geometry>
    </collision>
    <inertial>
      <origin rpy="0 0 0" xyz="0.013090 0.0180789 0.0445231"/>
      <mass value="0.024"/>
      <inertia ixx="0.0000098769" ixy="0.000000000806182" ixz="-0.00000000296036" iyy="0.000009848103" iyz="0.00000057639" izz="0.0000015674"/>
    </inertial>
  </link>
  <joint name="forkTine_to_forque" type="fixed">
    <parent link="forque"/>
    <child link="forkTine"/>
    <axis xyz="0 0 1"/>
    <origin rpy="0 3.141592653589793 4.1887902047863905" xyz="-0.0054 0.008 0.093"/>
  </joint>
  <link name="forkTip"/>
  <joint name="forkTip_to_forkTine" type="fixed">
    <child link="forkTip"/>
    <parent link="forkTine"/>
    <origin rpy="3.141592653589793 0 0" xyz="0.0135 0.007 0"/>
  </joint>
  <link name="FTSensor"/>
  <joint name="EE_to_FTSensor" type="fixed">
    <child link="FTSensor"/>
    <parent link="j2n6s200_end_effector"/>
    <origin rpy="0 0 0" xyz="0.0 0.0 0.092"/>
  </joint>
</robot>
